Workbook

Sheet Info
B2: TEMPLATE RAB EXCEL
B3: Sampel jasa penyusunan RAB, rekap material, dan progress
B4: Angka di file ini fiktif. Ganti sel kuning sebelum dipakai klien.
B6: Nama proyek | C6: Rumah tinggal contoh — tipe 36 (FIKTIF)
B7: Lokasi contoh | C7: Balikpapan
B8: Pemberi kerja | C8: Contoh Klien, bukan proyek nyata
B9: Penyusun | C9: Fajar Tri Suhartono
B10: Tanggal | C10: 2026-10-03
B11: Status | C11: Sampel jasa, bukan kontrak
B13: Cara pakai
B14: 1. Isi sel kuning di sheet Harga Satuan dan RAB (volume, harga).
B15: 2. Jumlah, rekap, PPN, dan material terhitung otomatis. Jangan ketik di sel hitam.
B16: 3. PPN diatur di Info!C16. Default 11%.
B17: 4. Sheet Rekap dan Material menarik angka dari RAB. Hijau = link antar sheet.
B18: 5. Sampel ini tidak memakai data klien lama.
B20: PPN | C20: 0.11 | D20: Ubah hanya sel ini
B22: Isi workbook
B23: Sheet | C23: Fungsi
B24: Info | C24: Identitas proyek dan tarif PPN
B25: Harga Satuan | C25: Daftar harga upah dan material (input)
B26: RAB | C26: Volume x harga satuan = jumlah, per kelompok pekerjaan
B27: Rekap | C27: Ringkasan biaya, PPN, dan grand total
B28: Material | C28: Kebutuhan material terpilih, terhubung ke volume RAB

Sheet Harga Satuan
A1: HARGA SATUAN PEKERJAAN — CONTOH FIKTIF
A2: =Info!C6&" | "&Info!C7&" | harga contoh, bukan harga pasar resmi" -> Rumah tinggal contoh — tipe 36 (FIKTIF) | Balikpapan | harga contoh, bukan harga pasar resmi
A4: Kode | B4: Uraian | C4: Satuan | D4: Harga satuan (Rp) | E4: Catatan
A5: P-01 | B5: Pembersihan lahan | C5: m2 | D5: 15000 | E5: Upah
A6: P-02 | B6: Bowplank | C6: m | D6: 35000 | E6: Upah + material ringan
A7: P-03 | B7: Galian tanah pondasi | C7: m3 | D7: 85000 | E7: Upah
A8: P-04 | B8: Urugan pasir bawah pondasi | C8: m3 | D8: 280000 | E8: Material + pasang
A9: P-05 | B9: Pondasi batu kali 1:4 | C9: m3 | D9: 1250000 | E9: Material + upah
A10: P-06 | B10: Sloof 15/20 beton K-225 | C10: m3 | D10: 2850000 | E10: Beton + bekisting + besi sederhana
A11: P-07 | B11: Kolom praktis 15/15 | C11: m3 | D11: 3200000 | E11: Termasuk besi pokok contoh
A12: P-08 | B12: Balok latai 15/20 | C12: m3 | D12: 3100000 | E12: Beton + bekisting
A13: P-09 | B13: Pelat lantai t=10 cm | C13: m2 | D13: 285000 | E13: Beton + wiremesh contoh
A14: P-10 | B14: Dinding bata merah 1/2 batu | C14: m2 | D14: 185000 | E14: Bata + spesi
A15: P-11 | B15: Plesteran 1:4 | C15: m2 | D15: 75000 | E15: Dua sisi dihitung terpisah di RAB
A16: P-12 | B16: Acian | C16: m2 | D16: 35000 | E16: Dua sisi dihitung terpisah di RAB
... A26: P-22 | B26: Pekerjaan lain-lain / tidak terduga | C26: ls | D26: 1 | E26: Diisi nominal di RAB, bukan di sini

Sheet RAB
A1: RENCANA ANGGARAN BIAYA — SAMPEL
A2: =Info!C6&" | "&Info!C7&" | penyusun: "&Info!C9 -> Rumah tinggal contoh — tipe 36 (FIKTIF) | Balikpapan | penyusun: Fajar Tri Suhartono
A3: Sel kuning = input. Sel hitam = rumus. Jangan timpa rumus.
A5: No | B5: Uraian pekerjaan | C5: Satuan | D5: Volume | E5: Harga satuan (Rp) | F5: Jumlah (Rp) | G5: Kode harga
A6: I. PEKERJAAN PERSIAPAN
A7: 1 | B7: Pembersihan lahan | C7: m2 | D7: 48 | E7: =IFERROR(VLOOKUP(G7,'Harga Satuan'!$A$5:$D$26,4,FALSE()),0) -> 15000 | F7: =D7*E7 -> 720000 | G7: P-01
A8: 2 | B8: Bowplank | C8: m | D8: 28 | E8: =IFERROR(VLOOKUP(G8,'Harga Satuan'!$A$5:$D$26,4,FALSE()),0) -> 35000 | F8: =D8*E8 -> 980000 | G8: P-02
A9: Subtotal | F9: =SUM(F7:F8) -> 1700000
A10: II. PEKERJAAN PONDASI DAN STRUKTUR
A11: 3 | B11: Galian tanah pondasi | C11: m3 | D11: 8.4 | E11: =IFERROR(VLOOKUP(G11,'Harga Satuan'!$A$5:$D$26,4,FALSE()),0) -> 85000 | F11: =D11*E11 -> 714000 | G11: P-03
A12: 4 | B12: Urugan pasir bawah pondasi | C12: m3 | D12: 1.6 | E12: =IFERROR(VLOOKUP(G12,'Harga Satuan'!$A$5:$D$26,4,FALSE()),0) -> 280000 | F12: =D12*E12 -> 448000 | G12: P-04
A13: 5 | B13: Pondasi batu kali 1:4 | C13: m3 | D13: 6.2 | E13: =IFERROR(VLOOKUP(G13,'Harga Satuan'!$A$5:$D$26,4,FALSE()),0) -> 1250000 | F13: =D13*E13 -> 7750000 | G13: P-05
A14: 6 | B14: Sloof 15/20 | C14: m3 | D14: 1.8 | E14: =IFERROR(VLOOKUP(G14,'Harga Satuan'!$A$5:$D$26,4,FALSE()),0) -> 2850000 | F14: =D14*E14 -> 5130000 | G14: P-06
A15: 7 | B15: Kolom praktis 15/15 | C15: m3 | D15: 0.9 | E15: =IFERROR(VLOOKUP(G15,'Harga Satuan'!$A$5:$D$26,4,FALSE()),0) -> 3200000 | F15: =D15*E15 -> 2880000 | G15: P-07
A16: 8 | B16: Balok latai 15/20 | C16: m3 | D16: 0.7 | E16: =IFERROR(VLOOKUP(G16,'Harga Satuan'!$A$5:$D$26,4,FALSE()),0) -> 3100000 | F16: =D16*E16 -> 2170000 | G16: P-08
A17: 9 | B17: Pelat lantai t=10 cm | C17: m2 | D17: 36 | E17: =IFERROR(VLOOKUP(G17,'Harga Satuan'!$A$5:$D$26,4,FALSE()),0) -> 285000 | F17: =D17*E17 -> 10260000 | G17: P-09
A18: Subtotal | F18: =SUM(F11:F17) -> 29352000
A19: III. PEKERJAAN DINDING DAN KUSEN
A20: 10 | B20: Dinding bata merah 1/2 batu | C20: m2 | D20: 92 | E20: =IFERROR(VLOOKUP(G20,'Harga Satuan'!$A$5:$D$26,4,FALSE()),0) -> 185000 | F20: =D20*E20 -> 17020000 | G20: P-10
A21: 11 | B21: Plesteran dua sisi | C21: m2 | D21: 184 | E21: =IFERROR(VLOOKUP(G21,'Harga Satuan'!$A$5:$D$26,4,FALSE()),0) -> 75000 | F21: =D21*E21 -> 13800000 | G21: P-11
A22: 12 | B22: Acian dua sisi | C22: m2 | D22: 184 | E22: =IFERROR(VLOOKUP(G22,'Harga Satuan'!$A$5:$D$26,4,FALSE()),0) -> 35000 | F22: =D22*E22 -> 6440000 | G22: P-12
A23: 13 | B23: Kusen, pintu, dan jendela | C23: m2 | D23: 9.5 | E23: =IFERROR(VLOOKUP(G23,'Harga Satuan'!$A$5:$D$26,4,FALSE()),0) -> 950000 | F23: =D23*E23 -> 9025000 | G23: P-13
A24: Subtotal | F24: =SUM(F20:F23) -> 46285000
A25: IV. PEKERJAAN ATAP DAN PLAFON
A26: 14 | B26: Atap baja ringan + genteng metal | C26: m2 | D26: 52 | E26: =IFERROR(VLOOKUP(G26,'Harga Satuan'!$A$5:$D$26,4,FALSE()),0) -> 285000 | F26: =D26*E26 -> 14820000 | G26: P-14
A27: 15 | B27: Plafon gypsum | C27: m2 | D27: 36 | E27: =IFERROR(VLOOKUP(G27,'Harga Satuan'!$A$5:$D$26,4,FALSE()),0) -> 165000 | F27: =D27*E27 -> 5940000 | G27: P-15
A28: Subtotal | F28: =SUM(F26:F27) -> 20760000
A29: V. PEKERJAAN FINISHING
A30: 16 | B30: Lantai keramik 40x40 | C30: m2 | D30: 36 | E30: =IFERROR(VLOOKUP(G30,'Harga Satuan'!$A$5:$D$26,4,FALSE()),0) -> 175000 | F30: =D30*E30 -> 6300000 | G30: P-16
A31: 17 | B31: Cat dinding interior | C31: m2 | D31: 110 | E31: =IFERROR(VLOOKUP(G31,'Harga Satuan'!$A$5:$D$26,4,FALSE()),0) -> 45000 | F31: =D31*E31 -> 4950000 | G31: P-17
A32: 18 | B32: Cat dinding eksterior | C32: m2 | D32: 74 | E32: =IFERROR(VLOOKUP(G32,'Harga Satuan'!$A$5:$D$26,4,FALSE()),0) -> 55000 | F32: =D32*E32 -> 4070000 | G32: P-18
A33: Subtotal | F33: =SUM(F30:F32) -> 15320000
A34: VI. PEKERJAAN MEP SEDERHANA
A35: 19 | B35: Instalasi listrik | C35: titik | D35: 18 | E35: =IFERROR(VLOOKUP(G35,'Harga Satuan'!$A$5:$D$26,4,FALSE()),0) -> 185000 | F35: =D35*E35 -> 3330000 | G35: P-19
A36: 20 | B36: Instalasi air bersih | C36: titik | D36: 6 | E36: =IFERROR(VLOOKUP(G36,'Harga Satuan'!$A$5:$D$26,4,FALSE()),0) -> 250000 | F36: =D36*E36 -> 1500000 | G36: P-20
A37: 21 | B37: Septictank sederhana | C37: unit | D37: 1 | E37: =IFERROR(VLOOKUP(G37,'Harga Satuan'!$A$5:$D$26,4,FALSE()),0) -> 3500000 | F37: =D37*E37 -> 3500000 | G37: P-21
A38: Subtotal | F38: =SUM(F35:F37) -> 8330000
A40: SUBTOTAL PEKERJAAN | F40: =F9+F18+F24+F28+F33+F38 -> 121747000
A41: ="PPN "&TEXT(Info!C20,"0%") -> PPN 11% | F41: =F40*Info!C20 -> 13392170
A42: GRAND TOTAL | F42: =F40+F41 -> 135139170
...

Sheet Rekap
A1: REKAPITULASI BIAYA
A2: =Info!C6&" | angka terhubung ke sheet RAB" -> Rumah tinggal contoh — tipe 36 (FIKTIF) | angka terhubung ke sheet RAB
A4: No | B4: Kelompok pekerjaan | C4: Jumlah (Rp) | D4: Bobot
A5: I | B5: Pekerjaan persiapan | C5: =RAB!F9 -> 1700000 | D5: =IF(C$11=0,0,C5/C$11) -> 0.013963383
A6: II | B6: Pondasi dan struktur | C6: =RAB!F18 -> 29352000 | D6: =IF(C$11=0,0,C6/C$11) -> 0.24109013
A7: III | B7: Dinding dan kusen | C7: =RAB!F24 -> 46285000 | D7: =IF(C$11=0,0,C7/C$11) -> 0.38017364
A8: IV | B8: Atap dan plafon | C8: =RAB!F28 -> 20760000 | D8: =IF(C$11=0,0,C8/C$11) -> 0.17051755
A9: V | B9: Finishing | C9: =RAB!F33 -> 15320000 | D9: =IF(C$11=0,0,C9/C$11) -> 0.12583472
A10: VI | B10: MEP sederhana | C10: =RAB!F38 -> 8330000 | D10: =IF(C$11=0,0,C10/C$11) -> 0.068420577
B11: Subtotal | C11: =SUM(C5:C10) -> 121747000 | D11: =SUM(D5:D10) -> 1
B13: PPN | C13: =RAB!F41 -> 13392170 | D13: =Info!C20 -> 0.11
B14: GRAND TOTAL | C14: =RAB!F42 -> 135139170
A16: Cara baca
A17: Bobot = bagian tiap kelompok terhadap subtotal. Ubah volume di RAB, rekap ikut berubah.

Sheet Material
A1: REKAP KEBUTUHAN MATERIAL — CONTOH
A2: Koefisien contoh. Bukan SNI resmi. Ganti sel kuning bila ada koefisien proyek.
A4: Material | B4: Satuan | C4: Volume induk | D4: Koefisien | E4: Kebutuhan | F4: Sumber volume
A5: Pasir urug | B5: m3 | C5: =RAB!D12 -> 1.6 | D5: 1 | E5: =C5*D5 -> 1.6 | F5: Urugan pasir
A6: Batu kali | B6: m3 | C6: =RAB!D13 -> 6.2 | D6: 1.2 | E6: =C6*D6 -> 7.44 | F6: Pondasi batu kali
A7: Semen portland | B7: zak | C7: =RAB!D13 -> 6.2 | D7: 4.5 | E7: =C7*D7 -> 27.9 | F7: Koefisien contoh pondasi
A8: Besi beton polos/ulir | B8: kg | C8: =RAB!D14 -> 1.8 | D8: 120 | E8: =C8*D8 -> 216 | F8: Koefisien contoh sloof
A9: Bata merah | B9: bh | C9: =RAB!D20 -> 92 | D9: 70 | E9: =C9*D9 -> 6440 | F9: Dinding 1/2 batu, contoh
A10: Semen plester | B10: zak | C10: =RAB!D21 -> 184 | D10: 0.15 | E10: =C10*D10 -> 27.6 | F10: Plesteran, contoh
A11: Genteng metal | B11: m2 | C11: =RAB!D26 -> 52 | D11: 1.1 | E11: =C11*D11 -> 57.2 | F11: Termasuk overlap contoh
A12: Rangka baja ringan | B12: m2 | C12: =RAB!D26 -> 52 | D12: 1 | E12: =C12*D12 -> 52 | F12: Ikut luas atap
A13: Keramik 40x40 | B13: m2 | C13: =RAB!D30 -> 36 | D13: 1.08 | E13: =C13*D13 -> 38.88 | F13: Termasuk waste contoh
A14: Cat tembok | B14: kg | C14: =(RAB!D31+RAB!D32) -> 184 | D14: 0.25 | E14: =C14*D14 -> 46 | F14: Interior + eksterior
A16: Kebutuhan = volume induk x koefisien. Volume induk mengikuti sheet RAB.
